31/03/2022 15:37:43  * Running on all addresses.
   WARNING: This is a development server. Do not use it in a production deployment.
31/03/2022 15:37:43  * Running on http://172.23.32.53:5000/ (Press CTRL+C to quit)
31/03/2022 15:40:13 127.0.0.1 - - [31/Mar/2022 15:40:13] "[32mGET /health-check HTTP/1.1[0m" 308 -
31/03/2022 15:40:13 127.0.0.1 - - [31/Mar/2022 15:40:13] "GET /health-check/ HTTP/1.1" 200 -
31/03/2022 15:40:42 127.0.0.1 - - [31/Mar/2022 15:40:42] "[32mPOST /health-check HTTP/1.1[0m" 308 -
31/03/2022 15:40:42 127.0.0.1 - - [31/Mar/2022 15:40:42] "POST /health-check/ HTTP/1.1" 200 -
06/04/2022 17:57:24  * Running on all addresses.
   WARNING: This is a development server. Do not use it in a production deployment.
06/04/2022 17:57:24  * Running on http://172.23.47.164:5000/ (Press CTRL+C to quit)
06/04/2022 18:01:11  * Running on all addresses.
   WARNING: This is a development server. Do not use it in a production deployment.
06/04/2022 18:01:11  * Running on http://172.23.47.164:5000/ (Press CTRL+C to quit)
06/04/2022 18:05:23 127.0.0.1 - - [06/Apr/2022 18:05:23] "[32mGET /health-check HTTP/1.1[0m" 308 -
06/04/2022 18:05:23 127.0.0.1 - - [06/Apr/2022 18:05:23] "GET /health-check/ HTTP/1.1" 200 -
06/04/2022 18:05:28 127.0.0.1 - - [06/Apr/2022 18:05:28] "[32mPOST /health-check HTTP/1.1[0m" 308 -
06/04/2022 18:05:28 127.0.0.1 - - [06/Apr/2022 18:05:28] "POST /health-check/ HTTP/1.1" 200 -
06/04/2022 18:06:53 127.0.0.1 - - [06/Apr/2022 18:06:53] "[33mGET /strokes HTTP/1.1[0m" 404 -
06/04/2022 18:07:24 Exception on /strokes/test [GET]
Traceback (most recent call last):
  File "/home/hari/.local/lib/python3.8/site-packages/flask/app.py", line 2447, in wsgi_app
    response = self.full_dispatch_request()
  File "/home/hari/.local/lib/python3.8/site-packages/flask/app.py", line 1952, in full_dispatch_request
    rv = self.handle_user_exception(e)
  File "/home/hari/.local/lib/python3.8/site-packages/flask/app.py", line 1821, in handle_user_exception
    reraise(exc_type, exc_value, tb)
  File "/home/hari/.local/lib/python3.8/site-packages/flask/_compat.py", line 39, in reraise
    raise value
  File "/home/hari/.local/lib/python3.8/site-packages/flask/app.py", line 1950, in full_dispatch_request
    rv = self.dispatch_request()
  File "/home/hari/.local/lib/python3.8/site-packages/flask/app.py", line 1936, in dispatch_request
    return self.view_functions[rule.endpoint](**req.view_args)
  File "/home/hari/CheckSante/psid_checkSante/machine_learning/brique_ML/routes/strokes_routes.py", line 16, in health_check
    return jsonify({"Ici on test si on risque une attaque !"}), 200
  File "/home/hari/.local/lib/python3.8/site-packages/flask/json/__init__.py", line 370, in jsonify
    dumps(data, indent=indent, separators=separators) + "\n",
  File "/home/hari/.local/lib/python3.8/site-packages/flask/json/__init__.py", line 211, in dumps
    rv = _json.dumps(obj, **kwargs)
  File "/usr/lib/python3.8/json/__init__.py", line 234, in dumps
    return cls(
  File "/usr/lib/python3.8/json/encoder.py", line 199, in encode
    chunks = self.iterencode(o, _one_shot=True)
  File "/usr/lib/python3.8/json/encoder.py", line 257, in iterencode
    return _iterencode(o, 0)
  File "/home/hari/.local/lib/python3.8/site-packages/flask/json/__init__.py", line 100, in default
    return _json.JSONEncoder.default(self, o)
  File "/usr/lib/python3.8/json/encoder.py", line 179, in default
    raise TypeError(f'Object of type {o.__class__.__name__} '
TypeError: Object of type set is not JSON serializable
06/04/2022 18:07:24 127.0.0.1 - - [06/Apr/2022 18:07:24] "[35m[1mGET /strokes/test HTTP/1.1[0m" 500 -
06/04/2022 18:08:34  * Running on all addresses.
   WARNING: This is a development server. Do not use it in a production deployment.
06/04/2022 18:08:34  * Running on http://172.23.47.164:5000/ (Press CTRL+C to quit)
06/04/2022 18:08:47 127.0.0.1 - - [06/Apr/2022 18:08:47] "[32mGET /health-check HTTP/1.1[0m" 308 -
06/04/2022 18:08:47 127.0.0.1 - - [06/Apr/2022 18:08:47] "GET /health-check/ HTTP/1.1" 200 -
06/04/2022 18:08:51 Exception on /strokes/test [GET]
Traceback (most recent call last):
  File "/home/hari/.local/lib/python3.8/site-packages/flask/app.py", line 2447, in wsgi_app
    response = self.full_dispatch_request()
  File "/home/hari/.local/lib/python3.8/site-packages/flask/app.py", line 1952, in full_dispatch_request
    rv = self.handle_user_exception(e)
  File "/home/hari/.local/lib/python3.8/site-packages/flask/app.py", line 1821, in handle_user_exception
    reraise(exc_type, exc_value, tb)
  File "/home/hari/.local/lib/python3.8/site-packages/flask/_compat.py", line 39, in reraise
    raise value
  File "/home/hari/.local/lib/python3.8/site-packages/flask/app.py", line 1950, in full_dispatch_request
    rv = self.dispatch_request()
  File "/home/hari/.local/lib/python3.8/site-packages/flask/app.py", line 1936, in dispatch_request
    return self.view_functions[rule.endpoint](**req.view_args)
  File "/home/hari/CheckSante/psid_checkSante/machine_learning/brique_ML/routes/strokes_routes.py", line 16, in strokes_test
    return jsonify({"Ici on test si on risque une attaque !"}), 200
  File "/home/hari/.local/lib/python3.8/site-packages/flask/json/__init__.py", line 370, in jsonify
    dumps(data, indent=indent, separators=separators) + "\n",
  File "/home/hari/.local/lib/python3.8/site-packages/flask/json/__init__.py", line 211, in dumps
    rv = _json.dumps(obj, **kwargs)
  File "/usr/lib/python3.8/json/__init__.py", line 234, in dumps
    return cls(
  File "/usr/lib/python3.8/json/encoder.py", line 199, in encode
    chunks = self.iterencode(o, _one_shot=True)
  File "/usr/lib/python3.8/json/encoder.py", line 257, in iterencode
    return _iterencode(o, 0)
  File "/home/hari/.local/lib/python3.8/site-packages/flask/json/__init__.py", line 100, in default
    return _json.JSONEncoder.default(self, o)
  File "/usr/lib/python3.8/json/encoder.py", line 179, in default
    raise TypeError(f'Object of type {o.__class__.__name__} '
TypeError: Object of type set is not JSON serializable
06/04/2022 18:08:51 127.0.0.1 - - [06/Apr/2022 18:08:51] "[35m[1mGET /strokes/test HTTP/1.1[0m" 500 -
06/04/2022 18:09:55  * Running on all addresses.
   WARNING: This is a development server. Do not use it in a production deployment.
06/04/2022 18:09:55  * Running on http://172.23.47.164:5000/ (Press CTRL+C to quit)
06/04/2022 18:10:15 127.0.0.1 - - [06/Apr/2022 18:10:15] "GET /strokes/test HTTP/1.1" 200 -
06/04/2022 18:12:27 127.0.0.1 - - [06/Apr/2022 18:12:27] "POST /strokes/test HTTP/1.1" 200 -
06/04/2022 18:14:05 127.0.0.1 - - [06/Apr/2022 18:14:05] "POST /strokes/test HTTP/1.1" 200 -
06/04/2022 18:15:06  * Running on all addresses.
   WARNING: This is a development server. Do not use it in a production deployment.
06/04/2022 18:15:06  * Running on http://172.23.47.164:5000/ (Press CTRL+C to quit)
06/04/2022 18:15:12 127.0.0.1 - - [06/Apr/2022 18:15:12] "GET /strokes/test HTTP/1.1" 200 -
06/04/2022 18:15:17 Exception on /strokes/test [POST]
Traceback (most recent call last):
  File "/home/hari/.local/lib/python3.8/site-packages/flask/app.py", line 2447, in wsgi_app
    response = self.full_dispatch_request()
  File "/home/hari/.local/lib/python3.8/site-packages/flask/app.py", line 1952, in full_dispatch_request
    rv = self.handle_user_exception(e)
  File "/home/hari/.local/lib/python3.8/site-packages/flask/app.py", line 1821, in handle_user_exception
    reraise(exc_type, exc_value, tb)
  File "/home/hari/.local/lib/python3.8/site-packages/flask/_compat.py", line 39, in reraise
    raise value
  File "/home/hari/.local/lib/python3.8/site-packages/flask/app.py", line 1950, in full_dispatch_request
    rv = self.dispatch_request()
  File "/home/hari/.local/lib/python3.8/site-packages/flask/app.py", line 1936, in dispatch_request
    return self.view_functions[rule.endpoint](**req.view_args)
  File "/home/hari/CheckSante/psid_checkSante/machine_learning/brique_ML/routes/strokes_routes.py", line 20, in strokes_test
    prediction = model_reglog_smote.predict(value)
  File "/home/hari/.local/lib/python3.8/site-packages/sklearn/linear_model/_base.py", line 425, in predict
    scores = self.decision_function(X)
  File "/home/hari/.local/lib/python3.8/site-packages/sklearn/linear_model/_base.py", line 407, in decision_function
    X = self._validate_data(X, accept_sparse="csr", reset=False)
  File "/home/hari/.local/lib/python3.8/site-packages/sklearn/base.py", line 566, in _validate_data
    X = check_array(X, **check_params)
  File "/home/hari/.local/lib/python3.8/site-packages/sklearn/utils/validation.py", line 769, in check_array
    raise ValueError(
ValueError: Expected 2D array, got 1D array instead:
array=[1.00000e+00 0.00000e+00 9.50000e+01 1.00000e+00 1.00000e+00 1.00000e+00
 1.00000e+00 1.00000e+00 2.28969e+03 3.60600e+02 2.00000e+00].
Reshape your data either using array.reshape(-1, 1) if your data has a single feature or array.reshape(1, -1) if it contains a single sample.
06/04/2022 18:15:17 127.0.0.1 - - [06/Apr/2022 18:15:17] "[35m[1mPOST /strokes/test HTTP/1.1[0m" 500 -
07/04/2022 00:24:34  * Running on all addresses.
   WARNING: This is a development server. Do not use it in a production deployment.
07/04/2022 00:24:34  * Running on http://172.23.47.164:5000/ (Press CTRL+C to quit)
07/04/2022 00:24:46 127.0.0.1 - - [07/Apr/2022 00:24:46] "GET /strokes/test HTTP/1.1" 200 -
07/04/2022 00:24:52 Exception on /strokes/test [POST]
Traceback (most recent call last):
  File "/home/hari/.local/lib/python3.8/site-packages/flask/app.py", line 2447, in wsgi_app
    response = self.full_dispatch_request()
  File "/home/hari/.local/lib/python3.8/site-packages/flask/app.py", line 1952, in full_dispatch_request
    rv = self.handle_user_exception(e)
  File "/home/hari/.local/lib/python3.8/site-packages/flask/app.py", line 1821, in handle_user_exception
    reraise(exc_type, exc_value, tb)
  File "/home/hari/.local/lib/python3.8/site-packages/flask/_compat.py", line 39, in reraise
    raise value
  File "/home/hari/.local/lib/python3.8/site-packages/flask/app.py", line 1950, in full_dispatch_request
    rv = self.dispatch_request()
  File "/home/hari/.local/lib/python3.8/site-packages/flask/app.py", line 1936, in dispatch_request
    return self.view_functions[rule.endpoint](**req.view_args)
  File "/home/hari/CheckSante/psid_checkSante/machine_learning/brique_ML/routes/strokes_routes.py", line 31, in strokes_test
    return jsonify("La prédiction envoyé par le model : ", prediction), 200
  File "/home/hari/.local/lib/python3.8/site-packages/flask/json/__init__.py", line 370, in jsonify
    dumps(data, indent=indent, separators=separators) + "\n",
  File "/home/hari/.local/lib/python3.8/site-packages/flask/json/__init__.py", line 211, in dumps
    rv = _json.dumps(obj, **kwargs)
  File "/usr/lib/python3.8/json/__init__.py", line 234, in dumps
    return cls(
  File "/usr/lib/python3.8/json/encoder.py", line 199, in encode
    chunks = self.iterencode(o, _one_shot=True)
  File "/usr/lib/python3.8/json/encoder.py", line 257, in iterencode
    return _iterencode(o, 0)
  File "/home/hari/.local/lib/python3.8/site-packages/flask/json/__init__.py", line 100, in default
    return _json.JSONEncoder.default(self, o)
  File "/usr/lib/python3.8/json/encoder.py", line 179, in default
    raise TypeError(f'Object of type {o.__class__.__name__} '
TypeError: Object of type ndarray is not JSON serializable
07/04/2022 00:24:52 127.0.0.1 - - [07/Apr/2022 00:24:52] "[35m[1mPOST /strokes/test HTTP/1.1[0m" 500 -
07/04/2022 00:25:32  * Running on all addresses.
   WARNING: This is a development server. Do not use it in a production deployment.
07/04/2022 00:25:32  * Running on http://172.23.47.164:5000/ (Press CTRL+C to quit)
07/04/2022 00:25:41 127.0.0.1 - - [07/Apr/2022 00:25:41] "GET /strokes/test HTTP/1.1" 200 -
07/04/2022 00:25:45 Exception on /strokes/test [POST]
Traceback (most recent call last):
  File "/home/hari/.local/lib/python3.8/site-packages/flask/app.py", line 2447, in wsgi_app
    response = self.full_dispatch_request()
  File "/home/hari/.local/lib/python3.8/site-packages/flask/app.py", line 1952, in full_dispatch_request
    rv = self.handle_user_exception(e)
  File "/home/hari/.local/lib/python3.8/site-packages/flask/app.py", line 1821, in handle_user_exception
    reraise(exc_type, exc_value, tb)
  File "/home/hari/.local/lib/python3.8/site-packages/flask/_compat.py", line 39, in reraise
    raise value
  File "/home/hari/.local/lib/python3.8/site-packages/flask/app.py", line 1950, in full_dispatch_request
    rv = self.dispatch_request()
  File "/home/hari/.local/lib/python3.8/site-packages/flask/app.py", line 1936, in dispatch_request
    return self.view_functions[rule.endpoint](**req.view_args)
  File "/home/hari/CheckSante/psid_checkSante/machine_learning/brique_ML/routes/strokes_routes.py", line 31, in strokes_test
    return jsonify({"La prédiction envoyé par le model : ", prediction}), 200
TypeError: unhashable type: 'numpy.ndarray'
07/04/2022 00:25:45 127.0.0.1 - - [07/Apr/2022 00:25:45] "[35m[1mPOST /strokes/test HTTP/1.1[0m" 500 -
07/04/2022 00:25:47 Exception on /strokes/test [POST]
Traceback (most recent call last):
  File "/home/hari/.local/lib/python3.8/site-packages/flask/app.py", line 2447, in wsgi_app
    response = self.full_dispatch_request()
  File "/home/hari/.local/lib/python3.8/site-packages/flask/app.py", line 1952, in full_dispatch_request
    rv = self.handle_user_exception(e)
  File "/home/hari/.local/lib/python3.8/site-packages/flask/app.py", line 1821, in handle_user_exception
    reraise(exc_type, exc_value, tb)
  File "/home/hari/.local/lib/python3.8/site-packages/flask/_compat.py", line 39, in reraise
    raise value
  File "/home/hari/.local/lib/python3.8/site-packages/flask/app.py", line 1950, in full_dispatch_request
    rv = self.dispatch_request()
  File "/home/hari/.local/lib/python3.8/site-packages/flask/app.py", line 1936, in dispatch_request
    return self.view_functions[rule.endpoint](**req.view_args)
  File "/home/hari/CheckSante/psid_checkSante/machine_learning/brique_ML/routes/strokes_routes.py", line 31, in strokes_test
    return jsonify({"La prédiction envoyé par le model : ", prediction}), 200
TypeError: unhashable type: 'numpy.ndarray'
07/04/2022 00:25:47 127.0.0.1 - - [07/Apr/2022 00:25:47] "[35m[1mPOST /strokes/test HTTP/1.1[0m" 500 -
07/04/2022 00:28:24  * Running on all addresses.
   WARNING: This is a development server. Do not use it in a production deployment.
07/04/2022 00:28:24  * Running on http://172.23.47.164:5000/ (Press CTRL+C to quit)
07/04/2022 00:28:30 Exception on /strokes/test [POST]
Traceback (most recent call last):
  File "/home/hari/.local/lib/python3.8/site-packages/flask/app.py", line 2447, in wsgi_app
    response = self.full_dispatch_request()
  File "/home/hari/.local/lib/python3.8/site-packages/flask/app.py", line 1952, in full_dispatch_request
    rv = self.handle_user_exception(e)
  File "/home/hari/.local/lib/python3.8/site-packages/flask/app.py", line 1821, in handle_user_exception
    reraise(exc_type, exc_value, tb)
  File "/home/hari/.local/lib/python3.8/site-packages/flask/_compat.py", line 39, in reraise
    raise value
  File "/home/hari/.local/lib/python3.8/site-packages/flask/app.py", line 1950, in full_dispatch_request
    rv = self.dispatch_request()
  File "/home/hari/.local/lib/python3.8/site-packages/flask/app.py", line 1936, in dispatch_request
    return self.view_functions[rule.endpoint](**req.view_args)
  File "/home/hari/CheckSante/psid_checkSante/machine_learning/brique_ML/routes/strokes_routes.py", line 31, in strokes_test
    return jsonify({"La prédiction envoyé par le model : ", float(prediction)}), 200
  File "/home/hari/.local/lib/python3.8/site-packages/flask/json/__init__.py", line 370, in jsonify
    dumps(data, indent=indent, separators=separators) + "\n",
  File "/home/hari/.local/lib/python3.8/site-packages/flask/json/__init__.py", line 211, in dumps
    rv = _json.dumps(obj, **kwargs)
  File "/usr/lib/python3.8/json/__init__.py", line 234, in dumps
    return cls(
  File "/usr/lib/python3.8/json/encoder.py", line 199, in encode
    chunks = self.iterencode(o, _one_shot=True)
  File "/usr/lib/python3.8/json/encoder.py", line 257, in iterencode
    return _iterencode(o, 0)
  File "/home/hari/.local/lib/python3.8/site-packages/flask/json/__init__.py", line 100, in default
    return _json.JSONEncoder.default(self, o)
  File "/usr/lib/python3.8/json/encoder.py", line 179, in default
    raise TypeError(f'Object of type {o.__class__.__name__} '
TypeError: Object of type set is not JSON serializable
07/04/2022 00:28:30 127.0.0.1 - - [07/Apr/2022 00:28:30] "[35m[1mPOST /strokes/test HTTP/1.1[0m" 500 -
07/04/2022 00:32:47  * Running on all addresses.
   WARNING: This is a development server. Do not use it in a production deployment.
07/04/2022 00:32:47  * Running on http://172.23.47.164:5000/ (Press CTRL+C to quit)
07/04/2022 00:32:54 Exception on /strokes/test [POST]
Traceback (most recent call last):
  File "/home/hari/.local/lib/python3.8/site-packages/flask/app.py", line 2447, in wsgi_app
    response = self.full_dispatch_request()
  File "/home/hari/.local/lib/python3.8/site-packages/flask/app.py", line 1952, in full_dispatch_request
    rv = self.handle_user_exception(e)
  File "/home/hari/.local/lib/python3.8/site-packages/flask/app.py", line 1821, in handle_user_exception
    reraise(exc_type, exc_value, tb)
  File "/home/hari/.local/lib/python3.8/site-packages/flask/_compat.py", line 39, in reraise
    raise value
  File "/home/hari/.local/lib/python3.8/site-packages/flask/app.py", line 1950, in full_dispatch_request
    rv = self.dispatch_request()
  File "/home/hari/.local/lib/python3.8/site-packages/flask/app.py", line 1936, in dispatch_request
    return self.view_functions[rule.endpoint](**req.view_args)
  File "/home/hari/CheckSante/psid_checkSante/machine_learning/brique_ML/routes/strokes_routes.py", line 31, in strokes_test
    return jsonify({"La prédiction envoyé par le model : ", prediction[0]}), 200
  File "/home/hari/.local/lib/python3.8/site-packages/flask/json/__init__.py", line 370, in jsonify
    dumps(data, indent=indent, separators=separators) + "\n",
  File "/home/hari/.local/lib/python3.8/site-packages/flask/json/__init__.py", line 211, in dumps
    rv = _json.dumps(obj, **kwargs)
  File "/usr/lib/python3.8/json/__init__.py", line 234, in dumps
    return cls(
  File "/usr/lib/python3.8/json/encoder.py", line 199, in encode
    chunks = self.iterencode(o, _one_shot=True)
  File "/usr/lib/python3.8/json/encoder.py", line 257, in iterencode
    return _iterencode(o, 0)
  File "/home/hari/.local/lib/python3.8/site-packages/flask/json/__init__.py", line 100, in default
    return _json.JSONEncoder.default(self, o)
  File "/usr/lib/python3.8/json/encoder.py", line 179, in default
    raise TypeError(f'Object of type {o.__class__.__name__} '
TypeError: Object of type set is not JSON serializable
07/04/2022 00:32:54 127.0.0.1 - - [07/Apr/2022 00:32:54] "[35m[1mPOST /strokes/test HTTP/1.1[0m" 500 -
07/04/2022 00:34:25  * Running on all addresses.
   WARNING: This is a development server. Do not use it in a production deployment.
07/04/2022 00:34:25  * Running on http://172.23.47.164:5000/ (Press CTRL+C to quit)
07/04/2022 00:34:30 Exception on /strokes/test [POST]
Traceback (most recent call last):
  File "/home/hari/.local/lib/python3.8/site-packages/flask/app.py", line 2447, in wsgi_app
    response = self.full_dispatch_request()
  File "/home/hari/.local/lib/python3.8/site-packages/flask/app.py", line 1952, in full_dispatch_request
    rv = self.handle_user_exception(e)
  File "/home/hari/.local/lib/python3.8/site-packages/flask/app.py", line 1821, in handle_user_exception
    reraise(exc_type, exc_value, tb)
  File "/home/hari/.local/lib/python3.8/site-packages/flask/_compat.py", line 39, in reraise
    raise value
  File "/home/hari/.local/lib/python3.8/site-packages/flask/app.py", line 1950, in full_dispatch_request
    rv = self.dispatch_request()
  File "/home/hari/.local/lib/python3.8/site-packages/flask/app.py", line 1936, in dispatch_request
    return self.view_functions[rule.endpoint](**req.view_args)
  File "/home/hari/CheckSante/psid_checkSante/machine_learning/brique_ML/routes/strokes_routes.py", line 31, in strokes_test
    return jsonify({"La prédiction envoyé par le model : ", str(prediction)}), 200
  File "/home/hari/.local/lib/python3.8/site-packages/flask/json/__init__.py", line 370, in jsonify
    dumps(data, indent=indent, separators=separators) + "\n",
  File "/home/hari/.local/lib/python3.8/site-packages/flask/json/__init__.py", line 211, in dumps
    rv = _json.dumps(obj, **kwargs)
  File "/usr/lib/python3.8/json/__init__.py", line 234, in dumps
    return cls(
  File "/usr/lib/python3.8/json/encoder.py", line 199, in encode
    chunks = self.iterencode(o, _one_shot=True)
  File "/usr/lib/python3.8/json/encoder.py", line 257, in iterencode
    return _iterencode(o, 0)
  File "/home/hari/.local/lib/python3.8/site-packages/flask/json/__init__.py", line 100, in default
    return _json.JSONEncoder.default(self, o)
  File "/usr/lib/python3.8/json/encoder.py", line 179, in default
    raise TypeError(f'Object of type {o.__class__.__name__} '
TypeError: Object of type set is not JSON serializable
07/04/2022 00:34:30 127.0.0.1 - - [07/Apr/2022 00:34:30] "[35m[1mPOST /strokes/test HTTP/1.1[0m" 500 -
07/04/2022 00:39:12  * Running on all addresses.
   WARNING: This is a development server. Do not use it in a production deployment.
07/04/2022 00:39:12  * Running on http://172.23.47.164:5000/ (Press CTRL+C to quit)
07/04/2022 00:39:53 127.0.0.1 - - [07/Apr/2022 00:39:53] "GET /strokes/test HTTP/1.1" 200 -
07/04/2022 00:40:08 Exception on /strokes/test [POST]
Traceback (most recent call last):
  File "/home/hari/.local/lib/python3.8/site-packages/flask/app.py", line 2447, in wsgi_app
    response = self.full_dispatch_request()
  File "/home/hari/.local/lib/python3.8/site-packages/flask/app.py", line 1952, in full_dispatch_request
    rv = self.handle_user_exception(e)
  File "/home/hari/.local/lib/python3.8/site-packages/flask/app.py", line 1821, in handle_user_exception
    reraise(exc_type, exc_value, tb)
  File "/home/hari/.local/lib/python3.8/site-packages/flask/_compat.py", line 39, in reraise
    raise value
  File "/home/hari/.local/lib/python3.8/site-packages/flask/app.py", line 1950, in full_dispatch_request
    rv = self.dispatch_request()
  File "/home/hari/.local/lib/python3.8/site-packages/flask/app.py", line 1936, in dispatch_request
    return self.view_functions[rule.endpoint](**req.view_args)
  File "/home/hari/CheckSante/psid_checkSante/machine_learning/brique_ML/routes/strokes_routes.py", line 32, in strokes_test
    resultat = json.dump(prediction.tolist())
TypeError: dump() missing 1 required positional argument: 'fp'
07/04/2022 00:40:08 127.0.0.1 - - [07/Apr/2022 00:40:08] "[35m[1mPOST /strokes/test HTTP/1.1[0m" 500 -
07/04/2022 00:40:36  * Running on all addresses.
   WARNING: This is a development server. Do not use it in a production deployment.
07/04/2022 00:40:36  * Running on http://172.23.47.164:5000/ (Press CTRL+C to quit)
07/04/2022 00:40:41 Exception on /strokes/test [POST]
Traceback (most recent call last):
  File "/home/hari/.local/lib/python3.8/site-packages/flask/app.py", line 2447, in wsgi_app
    response = self.full_dispatch_request()
  File "/home/hari/.local/lib/python3.8/site-packages/flask/app.py", line 1952, in full_dispatch_request
    rv = self.handle_user_exception(e)
  File "/home/hari/.local/lib/python3.8/site-packages/flask/app.py", line 1821, in handle_user_exception
    reraise(exc_type, exc_value, tb)
  File "/home/hari/.local/lib/python3.8/site-packages/flask/_compat.py", line 39, in reraise
    raise value
  File "/home/hari/.local/lib/python3.8/site-packages/flask/app.py", line 1950, in full_dispatch_request
    rv = self.dispatch_request()
  File "/home/hari/.local/lib/python3.8/site-packages/flask/app.py", line 1936, in dispatch_request
    return self.view_functions[rule.endpoint](**req.view_args)
  File "/home/hari/CheckSante/psid_checkSante/machine_learning/brique_ML/routes/strokes_routes.py", line 33, in strokes_test
    return jsonify({"La prédiction envoyé par le model : ", resultat}), 200
  File "/home/hari/.local/lib/python3.8/site-packages/flask/json/__init__.py", line 370, in jsonify
    dumps(data, indent=indent, separators=separators) + "\n",
  File "/home/hari/.local/lib/python3.8/site-packages/flask/json/__init__.py", line 211, in dumps
    rv = _json.dumps(obj, **kwargs)
  File "/usr/lib/python3.8/json/__init__.py", line 234, in dumps
    return cls(
  File "/usr/lib/python3.8/json/encoder.py", line 199, in encode
    chunks = self.iterencode(o, _one_shot=True)
  File "/usr/lib/python3.8/json/encoder.py", line 257, in iterencode
    return _iterencode(o, 0)
  File "/home/hari/.local/lib/python3.8/site-packages/flask/json/__init__.py", line 100, in default
    return _json.JSONEncoder.default(self, o)
  File "/usr/lib/python3.8/json/encoder.py", line 179, in default
    raise TypeError(f'Object of type {o.__class__.__name__} '
TypeError: Object of type set is not JSON serializable
07/04/2022 00:40:41 127.0.0.1 - - [07/Apr/2022 00:40:41] "[35m[1mPOST /strokes/test HTTP/1.1[0m" 500 -
07/04/2022 00:43:15  * Running on all addresses.
   WARNING: This is a development server. Do not use it in a production deployment.
07/04/2022 00:43:15  * Running on http://172.23.47.164:5000/ (Press CTRL+C to quit)
07/04/2022 00:43:19 Exception on /strokes/test [POST]
Traceback (most recent call last):
  File "/home/hari/.local/lib/python3.8/site-packages/flask/app.py", line 2447, in wsgi_app
    response = self.full_dispatch_request()
  File "/home/hari/.local/lib/python3.8/site-packages/flask/app.py", line 1952, in full_dispatch_request
    rv = self.handle_user_exception(e)
  File "/home/hari/.local/lib/python3.8/site-packages/flask/app.py", line 1821, in handle_user_exception
    reraise(exc_type, exc_value, tb)
  File "/home/hari/.local/lib/python3.8/site-packages/flask/_compat.py", line 39, in reraise
    raise value
  File "/home/hari/.local/lib/python3.8/site-packages/flask/app.py", line 1950, in full_dispatch_request
    rv = self.dispatch_request()
  File "/home/hari/.local/lib/python3.8/site-packages/flask/app.py", line 1936, in dispatch_request
    return self.view_functions[rule.endpoint](**req.view_args)
  File "/home/hari/CheckSante/psid_checkSante/machine_learning/brique_ML/routes/strokes_routes.py", line 33, in strokes_test
    return jsonify({"La prédiction envoyé par le model : ", resultat}), 200
  File "/home/hari/.local/lib/python3.8/site-packages/flask/json/__init__.py", line 370, in jsonify
    dumps(data, indent=indent, separators=separators) + "\n",
  File "/home/hari/.local/lib/python3.8/site-packages/flask/json/__init__.py", line 211, in dumps
    rv = _json.dumps(obj, **kwargs)
  File "/usr/lib/python3.8/json/__init__.py", line 234, in dumps
    return cls(
  File "/usr/lib/python3.8/json/encoder.py", line 199, in encode
    chunks = self.iterencode(o, _one_shot=True)
  File "/usr/lib/python3.8/json/encoder.py", line 257, in iterencode
    return _iterencode(o, 0)
  File "/home/hari/.local/lib/python3.8/site-packages/flask/json/__init__.py", line 100, in default
    return _json.JSONEncoder.default(self, o)
  File "/usr/lib/python3.8/json/encoder.py", line 179, in default
    raise TypeError(f'Object of type {o.__class__.__name__} '
TypeError: Object of type set is not JSON serializable
07/04/2022 00:43:19 127.0.0.1 - - [07/Apr/2022 00:43:19] "[35m[1mPOST /strokes/test HTTP/1.1[0m" 500 -
07/04/2022 00:44:06  * Running on all addresses.
   WARNING: This is a development server. Do not use it in a production deployment.
07/04/2022 00:44:06  * Running on http://172.23.47.164:5000/ (Press CTRL+C to quit)
07/04/2022 00:44:09 Exception on /strokes/test [POST]
Traceback (most recent call last):
  File "/home/hari/.local/lib/python3.8/site-packages/flask/app.py", line 2447, in wsgi_app
    response = self.full_dispatch_request()
  File "/home/hari/.local/lib/python3.8/site-packages/flask/app.py", line 1952, in full_dispatch_request
    rv = self.handle_user_exception(e)
  File "/home/hari/.local/lib/python3.8/site-packages/flask/app.py", line 1821, in handle_user_exception
    reraise(exc_type, exc_value, tb)
  File "/home/hari/.local/lib/python3.8/site-packages/flask/_compat.py", line 39, in reraise
    raise value
  File "/home/hari/.local/lib/python3.8/site-packages/flask/app.py", line 1950, in full_dispatch_request
    rv = self.dispatch_request()
  File "/home/hari/.local/lib/python3.8/site-packages/flask/app.py", line 1936, in dispatch_request
    return self.view_functions[rule.endpoint](**req.view_args)
  File "/home/hari/CheckSante/psid_checkSante/machine_learning/brique_ML/routes/strokes_routes.py", line 33, in strokes_test
    return jsonify({"La prédiction envoyé par le model : ": prediction}), 200
  File "/home/hari/.local/lib/python3.8/site-packages/flask/json/__init__.py", line 370, in jsonify
    dumps(data, indent=indent, separators=separators) + "\n",
  File "/home/hari/.local/lib/python3.8/site-packages/flask/json/__init__.py", line 211, in dumps
    rv = _json.dumps(obj, **kwargs)
  File "/usr/lib/python3.8/json/__init__.py", line 234, in dumps
    return cls(
  File "/usr/lib/python3.8/json/encoder.py", line 199, in encode
    chunks = self.iterencode(o, _one_shot=True)
  File "/usr/lib/python3.8/json/encoder.py", line 257, in iterencode
    return _iterencode(o, 0)
  File "/home/hari/.local/lib/python3.8/site-packages/flask/json/__init__.py", line 100, in default
    return _json.JSONEncoder.default(self, o)
  File "/usr/lib/python3.8/json/encoder.py", line 179, in default
    raise TypeError(f'Object of type {o.__class__.__name__} '
TypeError: Object of type ndarray is not JSON serializable
07/04/2022 00:44:09 127.0.0.1 - - [07/Apr/2022 00:44:09] "[35m[1mPOST /strokes/test HTTP/1.1[0m" 500 -
07/04/2022 00:44:34  * Running on all addresses.
   WARNING: This is a development server. Do not use it in a production deployment.
07/04/2022 00:44:34  * Running on http://172.23.47.164:5000/ (Press CTRL+C to quit)
07/04/2022 00:44:37 Exception on /strokes/test [POST]
Traceback (most recent call last):
  File "/home/hari/.local/lib/python3.8/site-packages/flask/app.py", line 2447, in wsgi_app
    response = self.full_dispatch_request()
  File "/home/hari/.local/lib/python3.8/site-packages/flask/app.py", line 1952, in full_dispatch_request
    rv = self.handle_user_exception(e)
  File "/home/hari/.local/lib/python3.8/site-packages/flask/app.py", line 1821, in handle_user_exception
    reraise(exc_type, exc_value, tb)
  File "/home/hari/.local/lib/python3.8/site-packages/flask/_compat.py", line 39, in reraise
    raise value
  File "/home/hari/.local/lib/python3.8/site-packages/flask/app.py", line 1950, in full_dispatch_request
    rv = self.dispatch_request()
  File "/home/hari/.local/lib/python3.8/site-packages/flask/app.py", line 1936, in dispatch_request
    return self.view_functions[rule.endpoint](**req.view_args)
  File "/home/hari/CheckSante/psid_checkSante/machine_learning/brique_ML/routes/strokes_routes.py", line 33, in strokes_test
    return jsonify({"La prédiction envoyé par le model : ": resultat}), 200
  File "/home/hari/.local/lib/python3.8/site-packages/flask/json/__init__.py", line 370, in jsonify
    dumps(data, indent=indent, separators=separators) + "\n",
  File "/home/hari/.local/lib/python3.8/site-packages/flask/json/__init__.py", line 211, in dumps
    rv = _json.dumps(obj, **kwargs)
  File "/usr/lib/python3.8/json/__init__.py", line 234, in dumps
    return cls(
  File "/usr/lib/python3.8/json/encoder.py", line 199, in encode
    chunks = self.iterencode(o, _one_shot=True)
  File "/usr/lib/python3.8/json/encoder.py", line 257, in iterencode
    return _iterencode(o, 0)
  File "/home/hari/.local/lib/python3.8/site-packages/flask/json/__init__.py", line 100, in default
    return _json.JSONEncoder.default(self, o)
  File "/usr/lib/python3.8/json/encoder.py", line 179, in default
    raise TypeError(f'Object of type {o.__class__.__name__} '
TypeError: Object of type bytes is not JSON serializable
07/04/2022 00:44:37 127.0.0.1 - - [07/Apr/2022 00:44:37] "[35m[1mPOST /strokes/test HTTP/1.1[0m" 500 -
07/04/2022 00:46:21  * Running on all addresses.
   WARNING: This is a development server. Do not use it in a production deployment.
07/04/2022 00:46:21  * Running on http://172.23.47.164:5000/ (Press CTRL+C to quit)
07/04/2022 00:46:27 Exception on /strokes/test [POST]
Traceback (most recent call last):
  File "/home/hari/.local/lib/python3.8/site-packages/flask/app.py", line 2447, in wsgi_app
    response = self.full_dispatch_request()
  File "/home/hari/.local/lib/python3.8/site-packages/flask/app.py", line 1952, in full_dispatch_request
    rv = self.handle_user_exception(e)
  File "/home/hari/.local/lib/python3.8/site-packages/flask/app.py", line 1821, in handle_user_exception
    reraise(exc_type, exc_value, tb)
  File "/home/hari/.local/lib/python3.8/site-packages/flask/_compat.py", line 39, in reraise
    raise value
  File "/home/hari/.local/lib/python3.8/site-packages/flask/app.py", line 1950, in full_dispatch_request
    rv = self.dispatch_request()
  File "/home/hari/.local/lib/python3.8/site-packages/flask/app.py", line 1936, in dispatch_request
    return self.view_functions[rule.endpoint](**req.view_args)
  File "/home/hari/CheckSante/psid_checkSante/machine_learning/brique_ML/routes/strokes_routes.py", line 33, in strokes_test
    return jsonify({"La prédiction envoyé par le model : ": prediction[0]}), 200
  File "/home/hari/.local/lib/python3.8/site-packages/flask/json/__init__.py", line 370, in jsonify
    dumps(data, indent=indent, separators=separators) + "\n",
  File "/home/hari/.local/lib/python3.8/site-packages/flask/json/__init__.py", line 211, in dumps
    rv = _json.dumps(obj, **kwargs)
  File "/usr/lib/python3.8/json/__init__.py", line 234, in dumps
    return cls(
  File "/usr/lib/python3.8/json/encoder.py", line 199, in encode
    chunks = self.iterencode(o, _one_shot=True)
  File "/usr/lib/python3.8/json/encoder.py", line 257, in iterencode
    return _iterencode(o, 0)
  File "/home/hari/.local/lib/python3.8/site-packages/flask/json/__init__.py", line 100, in default
    return _json.JSONEncoder.default(self, o)
  File "/usr/lib/python3.8/json/encoder.py", line 179, in default
    raise TypeError(f'Object of type {o.__class__.__name__} '
TypeError: Object of type int64 is not JSON serializable
07/04/2022 00:46:27 127.0.0.1 - - [07/Apr/2022 00:46:27] "[35m[1mPOST /strokes/test HTTP/1.1[0m" 500 -
07/04/2022 00:47:20  * Running on all addresses.
   WARNING: This is a development server. Do not use it in a production deployment.
07/04/2022 00:47:20  * Running on http://172.23.47.164:5000/ (Press CTRL+C to quit)
07/04/2022 00:47:24 127.0.0.1 - - [07/Apr/2022 00:47:24] "POST /strokes/test HTTP/1.1" 200 -
07/04/2022 00:48:49 127.0.0.1 - - [07/Apr/2022 00:48:49] "POST /strokes/test HTTP/1.1" 200 -
